未読メール数: 0
未読メール数: 0
未読メール数: 0
未読メール数: 0
未読メール数: 0
Traceback (most recent call last):
  File "/home/linlin/SES_project/mail_reader.py", line 13, in <module>
    django.setup()
  File "/home/linlin/SES_project/venv/lib/python3.12/site-packages/django/__init__.py", line 19, in setup
    configure_logging(settings.LOGGING_CONFIG, settings.LOGGING)
                      ^^^^^^^^^^^^^^^^^^^^^^^
  File "/home/linlin/SES_project/venv/lib/python3.12/site-packages/django/conf/__init__.py", line 81, in __getattr__
    self._setup(name)
  File "/home/linlin/SES_project/venv/lib/python3.12/site-packages/django/conf/__init__.py", line 68, in _setup
    self._wrapped = Settings(settings_module)
                    ^^^^^^^^^^^^^^^^^^^^^^^^^
  File "/home/linlin/SES_project/venv/lib/python3.12/site-packages/django/conf/__init__.py", line 166, in __init__
    mod = importlib.import_module(self.SETTINGS_MODULE)
          ^^^^^^^^^^^^^^^^^^^^^^^^^^^^^^^^^^^^^^^^^^^^^
  File "/usr/lib/python3.12/importlib/__init__.py", line 90, in import_module
    return _bootstrap._gcd_import(name[level:], package, level)
           ^^^^^^^^^^^^^^^^^^^^^^^^^^^^^^^^^^^^^^^^^^^^^^^^^^^^
  File "<frozen importlib._bootstrap>", line 1387, in _gcd_import
  File "<frozen importlib._bootstrap>", line 1360, in _find_and_load
  File "<frozen importlib._bootstrap>", line 1310, in _find_and_load_unlocked
  File "<frozen importlib._bootstrap>", line 488, in _call_with_frames_removed
  File "<frozen importlib._bootstrap>", line 1387, in _gcd_import
  File "<frozen importlib._bootstrap>", line 1360, in _find_and_load
  File "<frozen importlib._bootstrap>", line 1324, in _find_and_load_unlocked
ModuleNotFoundError: No module named 'SES_project'
Traceback (most recent call last):
  File "/home/linlin/SES_project/mail_reader.py", line 13, in <module>
    django.setup()
  File "/home/linlin/SES_project/venv/lib/python3.12/site-packages/django/__init__.py", line 19, in setup
    configure_logging(settings.LOGGING_CONFIG, settings.LOGGING)
                      ^^^^^^^^^^^^^^^^^^^^^^^
  File "/home/linlin/SES_project/venv/lib/python3.12/site-packages/django/conf/__init__.py", line 81, in __getattr__
    self._setup(name)
  File "/home/linlin/SES_project/venv/lib/python3.12/site-packages/django/conf/__init__.py", line 68, in _setup
    self._wrapped = Settings(settings_module)
                    ^^^^^^^^^^^^^^^^^^^^^^^^^
  File "/home/linlin/SES_project/venv/lib/python3.12/site-packages/django/conf/__init__.py", line 166, in __init__
    mod = importlib.import_module(self.SETTINGS_MODULE)
          ^^^^^^^^^^^^^^^^^^^^^^^^^^^^^^^^^^^^^^^^^^^^^
  File "/usr/lib/python3.12/importlib/__init__.py", line 90, in import_module
    return _bootstrap._gcd_import(name[level:], package, level)
           ^^^^^^^^^^^^^^^^^^^^^^^^^^^^^^^^^^^^^^^^^^^^^^^^^^^^
  File "<frozen importlib._bootstrap>", line 1387, in _gcd_import
  File "<frozen importlib._bootstrap>", line 1360, in _find_and_load
  File "<frozen importlib._bootstrap>", line 1310, in _find_and_load_unlocked
  File "<frozen importlib._bootstrap>", line 488, in _call_with_frames_removed
  File "<frozen importlib._bootstrap>", line 1387, in _gcd_import
  File "<frozen importlib._bootstrap>", line 1360, in _find_and_load
  File "<frozen importlib._bootstrap>", line 1324, in _find_and_load_unlocked
ModuleNotFoundError: No module named 'SES_project'
Traceback (most recent call last):
  File "/home/linlin/SES_project/mail_reader.py", line 14, in <module>
    django.setup()
  File "/home/linlin/SES_project/venv/lib/python3.12/site-packages/django/__init__.py", line 19, in setup
    configure_logging(settings.LOGGING_CONFIG, settings.LOGGING)
                      ^^^^^^^^^^^^^^^^^^^^^^^
  File "/home/linlin/SES_project/venv/lib/python3.12/site-packages/django/conf/__init__.py", line 81, in __getattr__
    self._setup(name)
  File "/home/linlin/SES_project/venv/lib/python3.12/site-packages/django/conf/__init__.py", line 68, in _setup
    self._wrapped = Settings(settings_module)
                    ^^^^^^^^^^^^^^^^^^^^^^^^^
  File "/home/linlin/SES_project/venv/lib/python3.12/site-packages/django/conf/__init__.py", line 166, in __init__
    mod = importlib.import_module(self.SETTINGS_MODULE)
          ^^^^^^^^^^^^^^^^^^^^^^^^^^^^^^^^^^^^^^^^^^^^^
  File "/usr/lib/python3.12/importlib/__init__.py", line 90, in import_module
    return _bootstrap._gcd_import(name[level:], package, level)
           ^^^^^^^^^^^^^^^^^^^^^^^^^^^^^^^^^^^^^^^^^^^^^^^^^^^^
  File "<frozen importlib._bootstrap>", line 1387, in _gcd_import
  File "<frozen importlib._bootstrap>", line 1360, in _find_and_load
  File "<frozen importlib._bootstrap>", line 1310, in _find_and_load_unlocked
  File "<frozen importlib._bootstrap>", line 488, in _call_with_frames_removed
  File "<frozen importlib._bootstrap>", line 1387, in _gcd_import
  File "<frozen importlib._bootstrap>", line 1360, in _find_and_load
  File "<frozen importlib._bootstrap>", line 1324, in _find_and_load_unlocked
ModuleNotFoundError: No module named 'SES_project'
Traceback (most recent call last):
  File "/home/linlin/SES_project/mail_reader.py", line 14, in <module>
    django.setup()
  File "/home/linlin/SES_project/venv/lib/python3.12/site-packages/django/__init__.py", line 19, in setup
    configure_logging(settings.LOGGING_CONFIG, settings.LOGGING)
                      ^^^^^^^^^^^^^^^^^^^^^^^
  File "/home/linlin/SES_project/venv/lib/python3.12/site-packages/django/conf/__init__.py", line 81, in __getattr__
    self._setup(name)
  File "/home/linlin/SES_project/venv/lib/python3.12/site-packages/django/conf/__init__.py", line 68, in _setup
    self._wrapped = Settings(settings_module)
                    ^^^^^^^^^^^^^^^^^^^^^^^^^
  File "/home/linlin/SES_project/venv/lib/python3.12/site-packages/django/conf/__init__.py", line 166, in __init__
    mod = importlib.import_module(self.SETTINGS_MODULE)
          ^^^^^^^^^^^^^^^^^^^^^^^^^^^^^^^^^^^^^^^^^^^^^
  File "/usr/lib/python3.12/importlib/__init__.py", line 90, in import_module
    return _bootstrap._gcd_import(name[level:], package, level)
           ^^^^^^^^^^^^^^^^^^^^^^^^^^^^^^^^^^^^^^^^^^^^^^^^^^^^
  File "<frozen importlib._bootstrap>", line 1387, in _gcd_import
  File "<frozen importlib._bootstrap>", line 1360, in _find_and_load
  File "<frozen importlib._bootstrap>", line 1310, in _find_and_load_unlocked
  File "<frozen importlib._bootstrap>", line 488, in _call_with_frames_removed
  File "<frozen importlib._bootstrap>", line 1387, in _gcd_import
  File "<frozen importlib._bootstrap>", line 1360, in _find_and_load
  File "<frozen importlib._bootstrap>", line 1324, in _find_and_load_unlocked
ModuleNotFoundError: No module named 'SES_project'
未読メール数: 0
未読メール数: 1
メール件名: 案件概要テスト
案件数: 1
Traceback (most recent call last):
  File "/home/linlin/SES_project/venv/lib/python3.12/site-packages/django/db/backends/utils.py", line 105, in _execute
    return self.cursor.execute(sql, params)
           ^^^^^^^^^^^^^^^^^^^^^^^^^^^^^^^^
  File "/home/linlin/SES_project/venv/lib/python3.12/site-packages/django/db/backends/sqlite3/base.py", line 360, in execute
    return super().execute(query, params)
           ^^^^^^^^^^^^^^^^^^^^^^^^^^^^^^
sqlite3.OperationalError: no such table: projects_project

The above exception was the direct cause of the following exception:

Traceback (most recent call last):
  File "/home/linlin/SES_project/mail_reader.py", line 95, in <module>
    fetch_emails_and_register_projects(allowed_domains)
  File "/home/linlin/SES_project/mail_reader.py", line 85, in fetch_emails_and_register_projects
    p.save()
  File "/home/linlin/SES_project/venv/lib/python3.12/site-packages/django/db/models/base.py", line 902, in save
    self.save_base(
  File "/home/linlin/SES_project/venv/lib/python3.12/site-packages/django/db/models/base.py", line 1008, in save_base
    updated = self._save_table(
              ^^^^^^^^^^^^^^^^^
  File "/home/linlin/SES_project/venv/lib/python3.12/site-packages/django/db/models/base.py", line 1169, in _save_table
    results = self._do_insert(
              ^^^^^^^^^^^^^^^^
  File "/home/linlin/SES_project/venv/lib/python3.12/site-packages/django/db/models/base.py", line 1210, in _do_insert
    return manager._insert(
           ^^^^^^^^^^^^^^^^
  File "/home/linlin/SES_project/venv/lib/python3.12/site-packages/django/db/models/manager.py", line 87, in manager_method
    return getattr(self.get_queryset(), name)(*args, **kwargs)
           ^^^^^^^^^^^^^^^^^^^^^^^^^^^^^^^^^^^^^^^^^^^^^^^^^^^
  File "/home/linlin/SES_project/venv/lib/python3.12/site-packages/django/db/models/query.py", line 1868, in _insert
    return query.get_compiler(using=using).execute_sql(returning_fields)
           ^^^^^^^^^^^^^^^^^^^^^^^^^^^^^^^^^^^^^^^^^^^^^^^^^^^^^^^^^^^^^
  File "/home/linlin/SES_project/venv/lib/python3.12/site-packages/django/db/models/sql/compiler.py", line 1882, in execute_sql
    cursor.execute(sql, params)
  File "/home/linlin/SES_project/venv/lib/python3.12/site-packages/django/db/backends/utils.py", line 122, in execute
    return super().execute(sql, params)
           ^^^^^^^^^^^^^^^^^^^^^^^^^^^^
  File "/home/linlin/SES_project/venv/lib/python3.12/site-packages/django/db/backends/utils.py", line 79, in execute
    return self._execute_with_wrappers(
           ^^^^^^^^^^^^^^^^^^^^^^^^^^^^
  File "/home/linlin/SES_project/venv/lib/python3.12/site-packages/django/db/backends/utils.py", line 92, in _execute_with_wrappers
    return executor(sql, params, many, context)
           ^^^^^^^^^^^^^^^^^^^^^^^^^^^^^^^^^^^^
  File "/home/linlin/SES_project/venv/lib/python3.12/site-packages/django/db/backends/utils.py", line 100, in _execute
    with self.db.wrap_database_errors:
  File "/home/linlin/SES_project/venv/lib/python3.12/site-packages/django/db/utils.py", line 91, in __exit__
    raise dj_exc_value.with_traceback(traceback) from exc_value
  File "/home/linlin/SES_project/venv/lib/python3.12/site-packages/django/db/backends/utils.py", line 105, in _execute
    return self.cursor.execute(sql, params)
           ^^^^^^^^^^^^^^^^^^^^^^^^^^^^^^^^
  File "/home/linlin/SES_project/venv/lib/python3.12/site-packages/django/db/backends/sqlite3/base.py", line 360, in execute
    return super().execute(query, params)
           ^^^^^^^^^^^^^^^^^^^^^^^^^^^^^^
django.db.utils.OperationalError: no such table: projects_project
未読メール数: 0
未読メール数: 0
未読メール数: 0
未読メール数: 0
未読メール数: 0
未読メール数: 0
未読メール数: 0
未読メール数: 0
未読メール数: 0
未読メール数: 3
メール件名: Re: [sales2-1] 
案件数: 0
未読メール数: 1
メール件名: [sales] 
案件数: 0
未読メール数: 0
